Traceback (most recent call last):
  File "/Users/vgreddy/.pyenv/versions/3.10.5/lib/python3.10/site-packages/nbclient/client.py", line 776, in _async_poll_for_reply
    msg = await ensure_async(self.kc.shell_channel.get_msg(timeout=new_timeout))
  File "/Users/vgreddy/.pyenv/versions/3.10.5/lib/python3.10/site-packages/jupyter_core/utils/__init__.py", line 182, in ensure_async
    result = await obj
  File "/Users/vgreddy/.pyenv/versions/3.10.5/lib/python3.10/site-packages/jupyter_client/channels.py", line 315, in get_msg
    raise Empty
_queue.Empty

During handling of the above exception, another exception occurred:

Traceback (most recent call last):
  File "/Users/vgreddy/.pyenv/versions/3.10.5/lib/python3.10/site-packages/jupyter_cache/executors/utils.py", line 58, in single_nb_execution
    executenb(
  File "/Users/vgreddy/.pyenv/versions/3.10.5/lib/python3.10/site-packages/nbclient/client.py", line 1265, in execute
    return NotebookClient(nb=nb, resources=resources, km=km, **kwargs).execute()
  File "/Users/vgreddy/.pyenv/versions/3.10.5/lib/python3.10/site-packages/jupyter_core/utils/__init__.py", line 166, in wrapped
    return loop.run_until_complete(inner)
  File "/Users/vgreddy/.pyenv/versions/3.10.5/lib/python3.10/asyncio/base_events.py", line 646, in run_until_complete
    return future.result()
  File "/Users/vgreddy/.pyenv/versions/3.10.5/lib/python3.10/site-packages/nbclient/client.py", line 703, in async_execute
    await self.async_execute_cell(
  File "/Users/vgreddy/.pyenv/versions/3.10.5/lib/python3.10/site-packages/nbclient/client.py", line 1002, in async_execute_cell
    exec_reply = await self.task_poll_for_reply
  File "/Users/vgreddy/.pyenv/versions/3.10.5/lib/python3.10/site-packages/nbclient/client.py", line 800, in _async_poll_for_reply
    error_on_timeout_execute_reply = await self._async_handle_timeout(timeout, cell)
  File "/Users/vgreddy/.pyenv/versions/3.10.5/lib/python3.10/site-packages/nbclient/client.py", line 852, in _async_handle_timeout
    raise CellTimeoutError.error_from_timeout_and_cell(
nbclient.exceptions.CellTimeoutError: A cell timed out while it was being executed, after 30 seconds.
The message was: Cell execution timed out.
Here is a preview of the cell contents:
-------------------
['# We start with our list of desired columns columns', 'lst = {"Genre": [], "Actors":[], "Director":[], "Plot":[], "Country":[], "Language":[], "imdbRating":[], "BoxOffice":[],\\', '       "imdbVotes":[], "Metascore":[], "Rated": []}', 'def append_frame(lst, df):', '    # Now for each title in the DataFrame, we want to make an API Request for every category listed.']
...
['    dataframe = pd.DataFrame(lst)', '    return dataframe', '', '# Now, we call this method on our data', 'api_response = append_frame(lst, data)']
-------------------

